<?xml version="1.0" ?>
<robot name="point_foot">
  <material name="black">
    <color rgba="0.0 0.0 0.0 1.0"/>
  </material>
  <material name="blue">
    <color rgba="0.0 0.0 0.8 1.0"/>
  </material>
  <material name="green">
    <color rgba="0.0 0.8 0.0 1.0"/>
  </material>
  <material name="grey">
    <color rgba="0.2 0.2 0.2 1.0"/>
  </material>
  <material name="silver">
    <color rgba="0.9137254901960784 0.9137254901960784 0.8470588235294118 1.0"/>
  </material>
  <material name="orange">
    <color rgba="1.0 0.4235294117647059 0.0392156862745098 1.0"/>
  </material>
  <material name="brown">
    <color rgba="0.8705882352941177 0.8117647058823529 0.7647058823529411 1.0"/>
  </material>
  <material name="red">
    <color rgba="0.8 0.0 0.0 1.0"/>
  </material>
  <material name="white">
    <color rgba="1.0 1.0 1.0 1.0"/>
  </material>
  <!-- ros_control plugin -->
  <gazebo>
    <plugin filename="libpointfoot_hw_sim.so" name="gazebo_ros_control">
      <robotNamespace>/</robotNamespace>
      <robotParam>point_foot_robot_description</robotParam>
      <robotSimType>pointfoot_gazebo/PointFootHWSim</robotSimType>
    </plugin>
  </gazebo>
  <gazebo>
    <plugin filename="libgazebo_ros_p3d.so" name="p3d_base_controller">
      <alwaysOn>true</alwaysOn>
      <updateRate>1000.0</updateRate>
      <bodyName>base</bodyName>
      <topicName>Odometry</topicName>
      <gaussianNoise>0</gaussianNoise>
      <frameName>world</frameName>
      <xyzOffsets>0 0 0</xyzOffsets>
      <rpyOffsets>0 0 0</rpyOffsets>
    </plugin>
  </gazebo>
  <gazebo reference="base">
    <maxVel>100.</maxVel>
    <self_collide>1</self_collide>
    <kp>10000.</kp>
    <kd>0.</kd>
  </gazebo>
<gazebo reference="stick_link">
    <mu1>0.2</mu1>
    <mu2>0.2</mu2>
    <material>Gazebo/White</material>
  </gazebo>
  <!-- LF leg -->
  <gazebo reference="abad_L">
    <mu1>0.2</mu1>
    <mu2>0.2</mu2>
    <self_collide>1</self_collide>
    <material>Gazebo/DarkGrey</material>
  </gazebo>
  <gazebo reference="hip_L">
    <mu1>0.2</mu1>
    <mu2>0.2</mu2>
    <self_collide>1</self_collide>
    <material>Gazebo/DarkGrey</material>
    <kp value="1000000.0"/>
    <kd value="1.0"/>
  </gazebo>
  <gazebo reference="knee_L">
    <mu1>0.2</mu1>
    <mu2>0.2</mu2>
    <self_collide>1</self_collide>
  </gazebo>
  <gazebo reference="foot_L">
    <mu1>0.6</mu1>
    <mu2>0.6</mu2>
    <self_collide>1</self_collide>
    <material>Gazebo/White</material>
    <kp value="1000000.0"/>
    <kd value="1.0"/>
  </gazebo>
  <gazebo reference="contact_L">
    <mu1>0.6</mu1>
    <mu2>0.6</mu2>
    <self_collide>1</self_collide>
    <material>Gazebo/White</material>
    <kp value="1000000.0"/>
    <kd value="1.0"/>
  </gazebo>
  <!-- RF leg -->
  <gazebo reference="abad_R">
    <mu1>0.2</mu1>
    <mu2>0.2</mu2>
    <self_collide>1</self_collide>
    <material>Gazebo/DarkGrey</material>
  </gazebo>
  <gazebo reference="hip_R">
    <mu1>0.2</mu1>
    <mu2>0.2</mu2>
    <self_collide>1</self_collide>
    <material>Gazebo/DarkGrey</material>
    <kp value="1000000.0"/>
    <kd value="1.0"/>
  </gazebo>
  <gazebo reference="knee_R">
    <mu1>0.2</mu1>
    <mu2>0.2</mu2>
    <self_collide>1</self_collide>
  </gazebo>
  <gazebo reference="foot_R">
    <mu1>0.6</mu1>
    <mu2>0.6</mu2>
    <self_collide>1</self_collide>
    <material>Gazebo/White</material>
    <kp value="1000000.0"/>
    <kd value="1.0"/>
  </gazebo>
  <gazebo reference="contact_R">
    <mu1>0.6</mu1>
    <mu2>0.6</mu2>
    <self_collide>1</self_collide>
    <material>Gazebo/White</material>
    <kp value="1000000.0"/>
    <kd value="1.0"/>
  </gazebo>

  <!-- Used for fixing robot to Gazebo 'base_link' -->
<link name="world"/>
<joint name="fixed" type="fixed">
  <origin rpy="0 0 0" xyz="0.0 0.0 0.1"/>
  <parent link="world"/>
  <child link="base"/>
</joint>
  
  <link name="base">
    <visual>
      <origin rpy="0 0 0" xyz="0 0 0"/>
      <geometry>
        <mesh filename="package://point_foot_robot_description/meshes/base_Link.STL"/>
      </geometry>
      <material name="">
        <color rgba="1 1 1 1"/>
      </material>
    </visual>
    <inertial>
      <origin rpy="0 0 0" xyz="-0.004 0.0 -0.008"/>
      <mass value="7.517"/>
      <inertia ixx="0.109557" ixy="-0.000005" ixz="0.025562" 
               iyy="0.072525" iyz="0.000009" izz="0.090606"/>
    </inertial>
  </link>
  <!-- Imu is fixed to the base link -->
  <joint name="limx_imu_joint" type="fixed">
    <origin rpy="0. 0. 0." xyz="0 0 0"/>
    <parent link="base"/>
    <child link="limx_imu"/>
  </joint>
  <!-- Imu link -->
  <link name="limx_imu">
    <inertial>
      <mass value="0.01"/>
      <origin rpy="0 0 0" xyz="0 0 0"/>
      <inertia ixx="0.000001" ixy="0" ixz="0" iyy="0.000001" iyz="0" izz="0.000001"/>
    </inertial>
    <visual>
      <origin rpy="0 0 0" xyz="0 0 0"/>
      <geometry>
        <box size="0.015 0.015 0.004"/>
      </geometry>
    </visual>
    <material name="orange">
      <color rgba="255 108 10 255"/>
    </material>
  </link>
  <gazebo reference="limx_imu">
    <material>Gazebo/Orange</material>
  </gazebo>
  <gazebo reference="limx_imu_joint">
    <disableFixedJointLumping>true</disableFixedJointLumping>
  </gazebo>

  <joint name="support_joint1" type="fixed">
       <origin rpy="0. 0. 0." xyz="0.2 0.15 -0.45"/>
       <parent link="base"/>
       <child link="support1"/>
   </joint>
   <link name="support1">
       <collision>
           <origin rpy="0 0 0" xyz="0 0 0"/>
           <geometry>
               <box size="0.015 0.015 0.004"/>
           </geometry>
       </collision>
   </link>
   <joint name="support_joint2" type="fixed">
       <origin rpy="0. 0. 0." xyz="-0.3 0.15 -0.45"/>
       <parent link="base"/>
       <child link="support2"/>
   </joint>
   <link name="support2">
       <collision>
           <origin rpy="0 0 0" xyz="0 0 0"/>
           <geometry>
               <box size="0.015 0.015 0.004"/>
           </geometry>
       </collision>
   </link>
   <joint name="support_joint3" type="fixed">
       <origin rpy="0. 0. 0." xyz="0.2 -0.15 -0.45"/>
       <parent link="base"/>
       <child link="support3"/>
   </joint>
   <link name="support3">
       <collision>
           <origin rpy="0 0 0" xyz="0 0 0"/>
           <geometry>
               <box size="0.015 0.015 0.004"/>
           </geometry>
       </collision>
   </link>
   <joint name="support_joint4" type="fixed">
       <origin rpy="0. 0. 0." xyz="-0.3 -0.15 -0.45"/>
       <parent link="base"/>
       <child link="support4"/>
   </joint>
   <link name="support4">
       <collision>
           <origin rpy="0 0 0" xyz="0 0 0"/>
           <geometry>
               <box size="0.015 0.015 0.004"/>
           </geometry>
       </collision>
   </link>

  <joint name="abad_L_joint" type="revolute">
    <origin rpy="0 0 0" xyz="0.001 0.099 -0.078"/>
    <parent link="base"/>
    <child link="abad_L"/>
    <axis xyz="1 0 0"/>
    <dynamics damping="0.05" friction="0.01"/>
    <limit effort="80.0" lower="-0.38397" upper="0.785398163" velocity="20.0"/>
  </joint>
  <link name="abad_L">
    <visual>
      <origin rpy="0 0 0" xyz="0 0 0"/>
      <geometry>
        <mesh filename="package://point_foot_robot_description/meshes/abad_L_Link.STL"/>
      </geometry>
      <material name=""/>
      <color rgba="0.79216 0.81961 0.93333 1"/>
    </visual>
    <inertial>
      <origin rpy="0 0 0" xyz="-0.065 0.047 0.0"/>
      <mass value="1.506"/>
      <inertia ixx="0.001528" ixy="0.000343" ixz="-0.000036" 
               iyy="0.001983" iyz="0.000041" izz="0.001925" />
    </inertial>
  </link>
  
  <joint name="hip_L_joint" type="revolute">
    <origin rpy="0 0 0" xyz="-0.08 0.019 0.0"/>
    <parent link="abad_L"/>
    <child link="hip_L"/>
    <axis xyz="0 1 0"/>
    <dynamics damping="0.05" friction="0.01"/>
    <limit effort="80.0" lower="-1.012291" upper="1.518436" velocity="20.0"/>
  </joint>
  <link name="hip_L">
    <visual>
      <origin rpy="0 0 0" xyz="0 0 0"/>
      <geometry>
        <mesh filename="package://point_foot_robot_description/meshes/hip_L_Link.STL" />
      </geometry>
      <material name=""/>
      <color rgba="0.79216 0.81961 0.93333 1"/>
    </visual>
    <inertial>
      <origin rpy="0 0 0" xyz="-0.025 -0.05 -0.0356"/>
      <mass value="2.1382"/>
      <inertia ixx="0.014469" ixy="0.001647" ixz="-0.007568" 
               iyy="0.018952" iyz="0.002308" izz="0.008104"/>
    </inertial>
  </link>

  <joint name="knee_L_joint" type="revolute">
    <origin rpy="0 0 0" xyz="-0.151 -0.019 -0.259"/>
    <parent link="hip_L"/>
    <child link="knee_L"/>
    <axis xyz="0 -1 0"/>
    <dynamics damping="0.05" friction="0.01"/>
    <limit effort="80" lower="-0.872665" upper="1.396263" velocity="20"/>
  </joint>
  <link name="knee_L">
    <visual>
      <origin rpy="0 0 0" xyz="0 0 0"/>
      <geometry>
        <mesh filename="package://point_foot_robot_description/meshes/knee_L_Link.STL" />
      </geometry>
      <material name=""/>
      <color rgba="0.79216 0.81961 0.93333 1"/>
    </visual>
    <collision>
      <origin rpy="0 0 0" xyz="0 0 0"/>
      <geometry>
        <sphere radius="0.03" />
      </geometry>
    </collision>
    <inertial>
      <origin rpy="0 0 0" xyz="0.0697 -0.002 0.046"/>
      <mass value="0.486"/>
      <inertia ixx="0.014195" ixy="0.000089" ixz="-0.000999" 
               iyy="0.016189" iyz="0.000245" izz="0.002054"/>
    </inertial>
  </link>

  <joint name="foot_L_joint" type="fixed">
    <origin rpy="0 0 0" xyz="0.15 0 -0.29066"/>
    <parent link="knee_L"/>
    <child link="foot_L"/>
    <axis xyz="0 0 0"/>
  </joint>
  <link name="foot_L">
    <visual>
      <origin rpy="0 0 0" xyz="0 0 0"/>
      <geometry>
        <mesh filename="package://point_foot_robot_description/meshes/foot_L_Link.STL"/>
      </geometry>
      <material name=""/>
      <color rgba="0.79216 0.81961 0.93333 1"/>
    </visual>
    <collision>
      <origin rpy="0 0 0" xyz="0 0 0.03"/>
      <geometry>
        <sphere radius="0.03" />
      </geometry>
    </collision>
    <inertial>
      <origin rpy="0 0 0" xyz="-0.00196 -1.0E-06 0.0383"/>
      <mass value="0.153"/>
      <inertia ixx="0.000084" ixy="0" ixz="0.000007" 
               iyy="0.000086" iyz="0" izz="0.000062"/>
    </inertial>
  </link>

  <link name="contact_L">
        <inertial>
            <origin xyz="-6.4629E-05 5.464E-05 0.0011936" rpy="0 0 0" />
            <mass value="1e-6" />
            <inertia ixx="1e-12" ixy="0" ixz="0" iyy="1e-12" iyz="0" izz="1e-12" />
        </inertial>
  </link>
  <joint name="contact_L_Joint" type="fixed">
      <origin xyz="0 0 0" rpy="0 0 0" />
      <parent link="foot_L" />
      <child link="contact_L" />
      <axis xyz="0 1 0" />
      <limit lower="-0" upper="0" effort="60" velocity="50" />
  </joint>
 
  <gazebo reference="foot_L_joint">
    <disableFixedJointLumping>true</disableFixedJointLumping>
  </gazebo>

  <gazebo reference="contact_L_Joint">
    <disableFixedJointLumping>true</disableFixedJointLumping>
  </gazebo>

  <transmission name="abad_L_tran">
    <type>transmission_interface/SimpleTransmission</type>
    <joint name="abad_L_joint">
      <hardwareInterface>hardware_interface/EffortJointInterface</hardwareInterface>
    </joint>
    <actuator name="abad_L_motor">
      <hardwareInterface>hardware_interface/EffortJointInterface</hardwareInterface>
      <mechanicalReduction>1</mechanicalReduction>
    </actuator>
  </transmission>
  <transmission name="hip_L_tran">
    <type>transmission_interface/SimpleTransmission</type>
    <joint name="hip_L_joint">
      <hardwareInterface>hardware_interface/EffortJointInterface</hardwareInterface>
    </joint>
    <actuator name="hip_L_motor">
      <hardwareInterface>hardware_interface/EffortJointInterface</hardwareInterface>
      <mechanicalReduction>1</mechanicalReduction>
    </actuator>
  </transmission>
  <transmission name="knee_L_tran">
    <type>transmission_interface/SimpleTransmission</type>
    <joint name="knee_L_joint">
      <hardwareInterface>hardware_interface/EffortJointInterface</hardwareInterface>
    </joint>
    <actuator name="knee_L_motor">
      <hardwareInterface>hardware_interface/EffortJointInterface</hardwareInterface>
      <mechanicalReduction>1</mechanicalReduction>
    </actuator>
  </transmission>

  <joint name="abad_R_joint" type="revolute">
    <origin rpy="0 0 0" xyz="0.001 -0.099 -0.078"/>
    <parent link="base"/>
    <child link="abad_R"/>
    <axis xyz="1 0 0"/>
    <dynamics damping="0.05" friction="0.01"/>
    <limit effort="80.0" lower="-1.39626" upper="0.785398163" velocity="20.0"/>
  </joint>
  <link name="abad_R">
    <visual>
      <origin rpy="0 0 0" xyz="0 0 0"/>
      <geometry>
        <mesh filename="package://point_foot_robot_description/meshes/abad_R_Link.STL"/>
      </geometry>
      <material name=""/>
      <color rgba="0.79216 0.81961 0.93333 1"/>
    </visual>
    <inertial>
      <origin rpy="0 0 0" xyz="-0.06850082 -0.04744926 0.00010940"/>
      <mass value="1.506"/>
      <inertia ixx="0.001528" ixy="-0.000343" ixz="-0.000036" 
               iyy="0.001983" iyz="-0.000041" izz="0.001925"/>
    </inertial>
  </link>

  <joint name="hip_R_joint" type="revolute">
    <origin rpy="0 0 0" xyz="-0.08 -0.019 0.0"/>
    <parent link="abad_R"/>
    <child link="hip_R"/>
    <axis xyz="0 -1 0"/>
    <dynamics damping="0.05" friction="0.01"/>
    <limit effort="80.0" lower="-1.518436" upper="1.012291" velocity="20.0"/>
  </joint>
  <link name="hip_R">
    <visual>
      <origin rpy="0 0 0" xyz="0 0 0"/>
      <geometry>
        <mesh filename="package://point_foot_robot_description/meshes/hip_R_Link.STL" />
      </geometry>
      <material name=""/>
      <color rgba="1 0.98039 0.6 1"/>
    </visual>
    <inertial>
      <origin rpy="0 0 0" xyz="-0.025184 0.05 -0.035614"/>
      <mass value="2.1382"/>
      <inertia ixx="0.014469" ixy="-0.001647" ixz="-0.007568" 
               iyy="0.018952" iyz="-0.002308" izz="0.008104"/>
    </inertial>
  </link>

  <joint name="knee_R_joint" type="revolute">
    <origin rpy="0 0 0" xyz="-0.151 0.019 -0.259"/>
    <parent link="hip_R"/>
    <child link="knee_R"/>
    <axis xyz="0 1 0"/>
    <dynamics damping="0.05" friction="0.01"/>
    <limit effort="80" lower="-1.396263" upper="0.872665" velocity="50"/>
  </joint>
  <link name="knee_R">
    <visual>
      <origin rpy="0 0 0" xyz="0 0 0"/>
      <geometry>
        <mesh filename="package://point_foot_robot_description/meshes/knee_R_Link.STL" />
      </geometry>
      <material name=""/>
      <color rgba="0.79216 0.81961 0.93333 1"/>
    </visual>
    <collision>
      <origin rpy="0 0 0" xyz="0 0 0"/>
      <geometry>
        <sphere radius="0.03" />
      </geometry>
    </collision>
    <inertial>
      <origin rpy="0 0 0" xyz="0.0697 0.002 0.046"/>
      <mass value="0.486"/>
      <inertia ixx="0.014195" ixy="-0.000089" ixz="-0.000999" 
               iyy="0.016189" iyz="-0.000245" izz="0.002054"/>
    </inertial>
  </link>

  <joint name="foot_R_joint" type="fixed"> 
    <origin rpy="0 0 0" xyz="0.15 0 -0.29066"/>
    <parent link="knee_R"/>
    <child link="foot_R"/>
    <axis xyz="0 0 0"/>
  </joint>
  <link name="foot_R">
    <visual>
      <origin rpy="0 0 0" xyz="0 0 0"/>
      <geometry>
        <mesh filename="package://point_foot_robot_description/meshes/foot_R_Link.STL"/>
      </geometry>
      <material name=""/>
      <color rgba="0.79216 0.81961 0.93333 1"/>
    </visual>
    <collision>
      <origin rpy="0 0 0" xyz="0 0 0.03"/>
      <geometry>
        <sphere radius="0.03" />
      </geometry>
    </collision>
    <inertial>
      <origin rpy="0 0 0" xyz="-0.00196 -1.0E-06 0.0383"/>
      <mass value="0.153"/>
      <inertia ixx="0.000084" ixy="0" ixz="0.000007" 
               iyy="0.000086" iyz="0" izz="0.000062"/>
    </inertial>
  </link>

  <link name="contact_R">
        <inertial>
            <origin xyz="-6.4629E-05 5.464E-05 0.0011936" rpy="0 0 0" />
            <mass value="1e-6" />
            <inertia ixx="1e-12" ixy="0" ixz="0" iyy="1e-12" iyz="0" izz="1e-12" />
        </inertial>
    </link>
    <joint name="contact_R_Joint" type="revolute">
        <origin xyz="0 0 0" rpy="0 0 0" />
        <parent link="foot_R" />
        <child link="contact_R" />
        <axis xyz="0 1 0" />
        <limit lower="-0" upper="0" effort="60" velocity="50" />
  </joint>

  <gazebo reference="contact_R_Joint">
    <disableFixedJointLumping>true</disableFixedJointLumping>
  </gazebo>
 
  <gazebo reference="foot_R_joint">
    <disableFixedJointLumping>true</disableFixedJointLumping>
  </gazebo>
  <transmission name="abad_R_tran">
    <type>transmission_interface/SimpleTransmission</type>
    <joint name="abad_R_joint">
      <hardwareInterface>hardware_interface/EffortJointInterface</hardwareInterface>
    </joint>
    <actuator name="abad_R_motor">
      <hardwareInterface>hardware_interface/EffortJointInterface</hardwareInterface>
      <mechanicalReduction>1</mechanicalReduction>
    </actuator>
  </transmission>
  <transmission name="hip_R_tran">
    <type>transmission_interface/SimpleTransmission</type>
    <joint name="hip_R_joint">
      <hardwareInterface>hardware_interface/EffortJointInterface</hardwareInterface>
    </joint>
    <actuator name="hip_R_motor">
      <hardwareInterface>hardware_interface/EffortJointInterface</hardwareInterface>
      <mechanicalReduction>1</mechanicalReduction>
    </actuator>
  </transmission>
  <transmission name="knee_R_tran">
    <type>transmission_interface/SimpleTransmission</type>
    <joint name="knee_R_joint">
      <hardwareInterface>hardware_interface/EffortJointInterface</hardwareInterface>
    </joint>
    <actuator name="knee_R_motor">
      <hardwareInterface>hardware_interface/EffortJointInterface</hardwareInterface>
      <mechanicalReduction>1</mechanicalReduction>
    </actuator>
  </transmission>
</robot>